<?xml version='1.0'?>
<sdf version='1.6'>
  <model name='climber'>
    <link name='base_link'>
      <pose frame=''>0 0 0 0 -0 0</pose>
      <inertial>
        <pose frame=''>0.445988 -0.622916 -0.46469 0 -0 0</pose>
        <mass>6.09652</mass>
        <inertia>
          <ixx>0.313067</ixx>
          <ixy>-3.86284e-07</ixy>
          <ixz>-1.59681e-05</ixz>
          <iyy>0.320487</iyy>
          <iyz>0.000281845</iyz>
          <izz>0.569376</izz>
        </inertia>
      </inertial>
      <collision name='base_link_collision'>
        <pose frame=''>0 0 0 0 -0 0</pose>
        <geometry>
          <mesh>
            <scale>1 1 1</scale>
            <uri>model://climber/meshes/base_link.STL</uri>
          </mesh>
        </geometry>
      </collision>
      <collision name='base_link_fixed_joint_lump__left_prim_track_collision_1'>
        <pose frame=''>0.14114 -0.29361 -0.48322 0 -0 0</pose>
        <geometry>
          <mesh>
            <scale>1 1 1</scale>
            <uri>model://climber/meshes/left_prim_track.STL</uri>
          </mesh>
        </geometry>
      </collision>
      <collision name='base_link_fixed_joint_lump__right_prim_track_collision_2'>
        <pose frame=''>0.13709 -0.90697 -0.49237 0 -0 0</pose>
        <geometry>
          <mesh>
            <scale>1 1 1</scale>
            <uri>model://climber/meshes/right_prim_track.STL</uri>
          </mesh>
        </geometry>
      </collision>
      <visual name='base_link_visual'>
        <pose frame=''>0 0 0 0 -0 0</pose>
        <geometry>
          <mesh>
            <scale>1 1 1</scale>
            <uri>model://climber/meshes/base_link.STL</uri>
          </mesh>
        </geometry>
      </visual>
      <visual name='base_link_fixed_joint_lump__left_prim_track_visual_1'>
        <pose frame=''>0.14114 -0.29361 -0.48322 0 -0 0</pose>
        <geometry>
          <mesh>
            <scale>1 1 1</scale>
            <uri>model://climber/meshes/left_prim_track.STL</uri>
          </mesh>
        </geometry>
      </visual>
      <visual name='base_link_fixed_joint_lump__right_prim_track_visual_2'>
        <pose frame=''>0.13709 -0.90697 -0.49237 0 -0 0</pose>
        <geometry>
          <mesh>
            <scale>1 1 1</scale>
            <uri>model://climber/meshes/right_prim_track.STL</uri>
          </mesh>
        </geometry>
      </visual>
      <sensor type="ray" name="sonar">
        <pose>0.25 0 0 0 0 0</pose>
        <update_rate>5</update_rate>
        <ray>
          <scan>
            <horizontal>
              <samples>5</samples>
              <resolution>1.0</resolution>
              <min_angle>-0.25</min_angle>
              <max_angle>0.25</max_angle>
            </horizontal>
            <vertical>
              <samples>5</samples>
              <resolution>1</resolution>
              <min_angle>-0.25</min_angle>
              <max_angle>0.25</max_angle>
            </vertical>
          </scan>
          <range>
            <min>0.01</min>
            <max>0.75</max>
            <resolution>0.01</resolution>
          </range>
        </ray>
        <plugin filename="libgazebo_ros_range.so" name="gazebo_ros_range">
          <gaussianNoise>0.005</gaussianNoise>
          <alwaysOn>true</alwaysOn>
          <updateRate>5</updateRate>
          <topicName>climber/ultrasonic_sensor</topicName>
          <frameName>sonar_link</frameName>
          <fov>0.5</fov>
          <radiation>ultrasound</radiation>
        </plugin>
      </sensor>
    </link>


    <link name='left_sec_arm'>
      <pose frame=''>0.75114 -0.21861 -0.48322 0 -0.061723 0</pose>
      <inertial>
        <pose frame=''>0 -0.058937 0.055713 0 -0 0</pose>
        <mass>4.74275</mass>
        <inertia>
          <ixx>0.0210189</ixx>
          <ixy>-1.23815e-19</ixy>
          <ixz>-2.85042e-06</ixz>
          <iyy>0.0264259</iyy>
          <iyz>6.86573e-20</iyz>
          <izz>0.0140734</izz>
        </inertia>
      </inertial>
      <collision name='left_sec_arm_collision'>
        <pose frame=''>0 0 0 0 -0 0</pose>
        <geometry>
          <mesh>
            <scale>1 1 1</scale>
            <uri>model://climber/meshes/left_sec_arm.STL</uri>
          </mesh>
        </geometry>
      </collision>
      <visual name='left_sec_arm_visual'>
        <pose frame=''>0 0 0 0 -0 0</pose>
        <geometry>
          <mesh>
            <scale>1 1 1</scale>
            <uri>model://climber/meshes/left_sec_arm.STL</uri>
          </mesh>
        </geometry>
      </visual>
    </link>
    <joint name='left_sec_arm_to_base' type='revolute'>
      <child>left_sec_arm</child>
      <parent>base_link</parent>
      <axis>
        <xyz>0 1 0</xyz>
        <limit>
          <lower>0</lower>
          <upper>3.142</upper>
          <effort>100</effort>
          <velocity>10</velocity>
        </limit>
        <dynamics>
          <spring_reference>0</spring_reference>
          <spring_stiffness>0</spring_stiffness>
        </dynamics>
        <use_parent_model_frame>1</use_parent_model_frame>
      </axis>
    </joint>
    <link name='left_wheel_back'>
      <pose frame=''>0.14114 -0.31861 -0.48322 0 -0 0</pose>
      <inertial>
        <pose frame=''>1e-06 -0 -3e-06 0 -0 0</pose>
        <mass>1.4345</mass>
        <inertia>
          <ixx>0.00384907</ixx>
          <ixy>-2.26173e-20</ixy>
          <ixz>-8.81138e-09</ixz>
          <iyy>0.00713063</iyy>
          <iyz>-3.1138e-20</iyz>
          <izz>0.00384911</izz>
        </inertia>
      </inertial>
      <collision name='left_wheel_back_collision'>
        <pose frame=''>0 0 0 0 -0 0</pose>
        <geometry>
          <mesh>
            <scale>1 1 1</scale>
            <uri>model://climber/meshes/left_wheel_back.STL</uri>
          </mesh>
        </geometry>
      </collision>
      <visual name='left_wheel_back_visual'>
        <pose frame=''>0 0 0 0 -0 0</pose>
        <geometry>
          <mesh>
            <scale>1 1 1</scale>
            <uri>model://climber/meshes/left_wheel_back.STL</uri>
          </mesh>
        </geometry>
      </visual>
    </link>
    <joint name='left_wheel_back_to_base' type='revolute'>
      <child>left_wheel_back</child>
      <parent>base_link</parent>
      <axis>
        <xyz>0 -1 0</xyz>
        <limit>
          <lower>-1e+16</lower>
          <upper>1e+16</upper>
        </limit>
        <dynamics>
          <spring_reference>0</spring_reference>
          <spring_stiffness>0</spring_stiffness>
        </dynamics>
        <use_parent_model_frame>1</use_parent_model_frame>
      </axis>
    </joint>
    <link name='payload'>
      <pose frame=''>0.44623 -0.37861 -0.053223 0 -0.009323 0</pose>
      <inertial>
        <pose frame=''>0.000436 -0.24533 -0.092166 0 -0 0</pose>
        <mass>5.29624</mass>
        <inertia>
          <ixx>0.218846</ixx>
          <ixy>0.000537001</ixy>
          <ixz>-1.32545e-07</ixz>
          <iyy>0.31709</iyy>
          <iyz>1.00245e-07</iyz>
          <izz>0.457796</izz>
        </inertia>
      </inertial>
      <collision name='payload_collision'>
        <pose frame=''>0 0 0 0 -0 0</pose>
        <geometry>
          <mesh>
            <scale>1 1 1</scale>
            <uri>model://climber/meshes/payload.STL</uri>
          </mesh>
        </geometry>
      </collision>
      <visual name='payload_visual'>
        <pose frame=''>0 0 0 0 -0 0</pose>
        <geometry>
          <mesh>
            <scale>1 1 1</scale>
            <uri>model://climber/meshes/payload.STL</uri>
          </mesh>
        </geometry>
      </visual>
    </link>
    <joint name='payload_to_base' type='revolute'>
      <child>payload</child>
      <parent>base_link</parent>
      <axis>
        <xyz>0 -1 0</xyz>
        <limit>
          <lower>-1.047</lower>
          <upper>1.047</upper>
          <effort>100</effort>
          <velocity>10</velocity>
        </limit>
        <dynamics>
          <damping>0</damping>
          <friction>0.1</friction>
          <spring_reference>0</spring_reference>
          <spring_stiffness>0</spring_stiffness>
        </dynamics>
        <use_parent_model_frame>1</use_parent_model_frame>
      </axis>
    </joint>
    <link name='right_sec_arm'>
      <pose frame=''>0.75114 -0.90861 -0.48322 0 -0.052205 0</pose>
      <inertial>
        <pose frame=''>-0.000763 -0.061063 0.055708 0 -0 0</pose>
        <mass>4.74275</mass>
        <inertia>
          <ixx>0.0210175</ixx>
          <ixy>-3.22321e-18</ixy>
          <ixz>9.78806e-05</ixz>
          <iyy>0.0264259</iyy>
          <iyz>-3.25716e-18</iyz>
          <izz>0.0140748</izz>
        </inertia>
      </inertial>
      <collision name='right_sec_arm_collision'>
        <pose frame=''>0 0 0 0 -0 0</pose>
        <geometry>
          <mesh>
            <scale>1 1 1</scale>
            <uri>model://climber/meshes/right_sec_arm.STL</uri>
          </mesh>
        </geometry>
      </collision>
      <visual name='right_sec_arm_visual'>
        <pose frame=''>0 0 0 0 -0 0</pose>
        <geometry>
          <mesh>
            <scale>1 1 1</scale>
            <uri>model://climber/meshes/right_sec_arm.STL</uri>
          </mesh>
        </geometry>
      </visual>
    </link>
    <joint name='right_sec_arm_to_base' type='revolute'>
      <child>right_sec_arm</child>
      <parent>base_link</parent>
      <axis>
        <xyz>0 1 0</xyz>
        <limit>
          <lower>0</lower>
          <upper>3.142</upper>
          <effort>100</effort>
          <velocity>10</velocity>
        </limit>
        <dynamics>
          <spring_reference>0</spring_reference>
          <spring_stiffness>0</spring_stiffness>
        </dynamics>
        <use_parent_model_frame>1</use_parent_model_frame>
      </axis>
    </joint>
    <link name='right_wheel_back'>
      <pose frame=''>0.14114 -0.92861 -0.48322 0 -0 0</pose>
      <inertial>
        <pose frame=''>1e-06 -0 -3e-06 0 -0 0</pose>
        <mass>1.4345</mass>
        <inertia>
          <ixx>0.00384907</ixx>
          <ixy>8.51972e-20</ixy>
          <ixz>-8.89488e-09</ixz>
          <iyy>0.00713063</iyy>
          <iyz>-2.61399e-20</iyz>
          <izz>0.00384911</izz>
        </inertia>
      </inertial>
      <collision name='right_wheel_back_collision'>
        <pose frame=''>0 0 0 0 -0 0</pose>
        <geometry>
          <mesh>
            <scale>1 1 1</scale>
            <uri>model://climber/meshes/right_wheel_back.STL</uri>
          </mesh>
        </geometry>
      </collision>
      <visual name='right_wheel_back_visual'>
        <pose frame=''>0 0 0 0 -0 0</pose>
        <geometry>
          <mesh>
            <scale>1 1 1</scale>
            <uri>model://climber/meshes/right_wheel_back.STL</uri>
          </mesh>
        </geometry>
      </visual>
    </link>
    <joint name='right_wheel_back_to_base' type='revolute'>
      <child>right_wheel_back</child>
      <parent>base_link</parent>
      <axis>
        <xyz>0 -1 0</xyz>
        <limit>
          <lower>-1e+16</lower>
          <upper>1e+16</upper>
        </limit>
        <dynamics>
          <spring_reference>0</spring_reference>
          <spring_stiffness>0</spring_stiffness>
        </dynamics>
        <use_parent_model_frame>1</use_parent_model_frame>
      </axis>
    </joint>
  
    <link name='cam_link'>
      <pose frame=''>0.8 -0.56361 -0.48322 0 0 0</pose>
      <inertial>
        <mass>0.1</mass>
        <inertia>
          <ixx>1</ixx>
          <ixy>0</ixy>
          <ixz>0</ixz>
          <iyy>1</iyy>
          <iyz>0</iyz>
          <izz>1</izz>
        </inertia>
        <pose frame=''>0.8 -0.56361 -0.48322 0 0 0</pose>
      </inertial>
      <self_collide>0</self_collide>
      <kinematic>0</kinematic>
      <sensor name='camera1' type='camera'>
        <camera name="head">
          <horizontal_fov>1.3962634</horizontal_fov>
          <image>
            <width>800</width>
            <height>800</height>
            <format>R8G8B8</format>
          </image>
          <clip>
            <near>0.02</near>
            <far>300</far>
          </clip>
        </camera>
        <always_on>1</always_on>
        <update_rate>30</update_rate>
        <visualize>0</visualize>
        <plugin name="camera_controller" filename="libgazebo_ros_camera.so">
          <alwaysOn>true</alwaysOn>
          <updateRate>0.0</updateRate>
          <cameraName>climber/camera</cameraName>
          <imageTopicName>climber/image_raw</imageTopicName>
          <cameraInfoTopicName>climber/camera_info</cameraInfoTopicName>
          <frameName>camera_link</frameName>
          <hackBaseline>0.07</hackBaseline>
          <distortionK1>0.0</distortionK1>
          <distortionK2>0.0</distortionK2>
          <distortionK3>0.0</distortionK3>
          <distortionT1>0.0</distortionT1>
          <distortionT2>0.0</distortionT2>
        </plugin>
      </sensor>
    </link>
    <joint name='camera_to_base' type='fixed'>
      <child>cam_link</child>
      <parent>base_link</parent>
    </joint>

    <plugin name="p3d_base_controller" filename="libgazebo_ros_p3d.so">
      <alwaysOn>true</alwaysOn>
      <updateRate>50.0</updateRate>
      <bodyName>base_link</bodyName>
      <topicName>climber/odom</topicName>
      <gaussianNoise>0.01</gaussianNoise>
      <frameName>world</frameName>
      <xyzOffsets>0 0 0</xyzOffsets>
      <rpyOffsets>0 0 0</rpyOffsets>
    </plugin>

    <plugin name="imu_plugin" filename="libgazebo_ros_imu.so">
      <alwaysOn>true</alwaysOn>
      <bodyName>base_footprint</bodyName>
      <topicName>climber/imu</topicName>
      <serviceName>climber/imu_service</serviceName>
      <gaussianNoise>0.0</gaussianNoise>
      <updateRate>20.0</updateRate>
    </plugin>
  </model>
</sdf>
